WARNING 2023-06-06 07:17:49,065 django.request Thread-1 (process_request_thread) 140585997432384 log log.py 241 django.request log_response 20797 Not Found: /person/get_all_persons_data/ 
 path: /home/faridh/Desktop/DeltaProject/venv/lib/python3.10/site-packages/django/utils/log.py

WARNING 2023-06-06 07:17:49,069 django.server Thread-1 (process_request_thread) 140585997432384 basehttp basehttp.py 212 django.server log_message 20797 "POST /person/get_all_persons_data/ HTTP/1.1" 404 7938 
 path: /home/faridh/Desktop/DeltaProject/venv/lib/python3.10/site-packages/django/core/servers/basehttp.py

ERROR 2023-06-06 07:49:07,652 django.request Thread-2 (process_request_thread) 140629232318016 log log.py 241 django.request log_response 25172 Internal Server Error: /person/get-person/ 
 path: /home/faridh/Desktop/DeltaProject/venv/lib/python3.10/site-packages/django/utils/log.py

ERROR 2023-06-06 07:49:07,662 django.server Thread-2 (process_request_thread) 140629232318016 basehttp basehttp.py 212 django.server log_message 25172 "POST /person/get-person/ HTTP/1.1" 500 530 
 path: /home/faridh/Desktop/DeltaProject/venv/lib/python3.10/site-packages/django/core/servers/basehttp.py

ERROR 2023-06-06 07:53:43,427 django.request Thread-3 (process_request_thread) 140629232318016 log log.py 241 django.request log_response 25172 Internal Server Error: /person/get-person/ 
 path: /home/faridh/Desktop/DeltaProject/venv/lib/python3.10/site-packages/django/utils/log.py

ERROR 2023-06-06 07:53:43,435 django.server Thread-3 (process_request_thread) 140629232318016 basehttp basehttp.py 212 django.server log_message 25172 "POST /person/get-person/ HTTP/1.1" 500 530 
 path: /home/faridh/Desktop/DeltaProject/venv/lib/python3.10/site-packages/django/core/servers/basehttp.py

ERROR 2023-06-06 07:55:15,332 django.request Thread-8 (process_request_thread) 140629232318016 log log.py 241 django.request log_response 25172 Internal Server Error: /person/get-person/ 
 path: /home/faridh/Desktop/DeltaProject/venv/lib/python3.10/site-packages/django/utils/log.py

ERROR 2023-06-06 07:55:15,335 django.server Thread-8 (process_request_thread) 140629232318016 basehttp basehttp.py 212 django.server log_message 25172 "POST /person/get-person/ HTTP/1.1" 500 530 
 path: /home/faridh/Desktop/DeltaProject/venv/lib/python3.10/site-packages/django/core/servers/basehttp.py

ERROR 2023-06-06 07:56:23,428 django.request Thread-10 (process_request_thread) 140629232318016 log log.py 241 django.request log_response 25172 Internal Server Error: /person/get-person/ 
 path: /home/faridh/Desktop/DeltaProject/venv/lib/python3.10/site-packages/django/utils/log.py

ERROR 2023-06-06 07:56:23,432 django.server Thread-10 (process_request_thread) 140629232318016 basehttp basehttp.py 212 django.server log_message 25172 "POST /person/get-person/ HTTP/1.1" 500 530 
 path: /home/faridh/Desktop/DeltaProject/venv/lib/python3.10/site-packages/django/core/servers/basehttp.py

ERROR 2023-06-06 07:56:28,753 django.request Thread-11 (process_request_thread) 140629232318016 log log.py 241 django.request log_response 25172 Internal Server Error: /person/get-person/ 
 path: /home/faridh/Desktop/DeltaProject/venv/lib/python3.10/site-packages/django/utils/log.py

ERROR 2023-06-06 07:56:28,755 django.server Thread-11 (process_request_thread) 140629232318016 basehttp basehttp.py 212 django.server log_message 25172 "POST /person/get-person/ HTTP/1.1" 500 530 
 path: /home/faridh/Desktop/DeltaProject/venv/lib/python3.10/site-packages/django/core/servers/basehttp.py

WARNING 2023-06-06 08:35:12,060 django.request Thread-3 (process_request_thread) 139885992560192 log log.py 241 django.request log_response 38718 Not Found: /person/add_or_change_person_profile_image/ 
 path: /home/faridh/Desktop/DeltaProject/venv/lib/python3.10/site-packages/django/utils/log.py

WARNING 2023-06-06 08:35:12,066 django.server Thread-3 (process_request_thread) 139885992560192 basehttp basehttp.py 212 django.server log_message 38718 "POST /person/add_or_change_person_profile_image/ HTTP/1.1" 404 7970 
 path: /home/faridh/Desktop/DeltaProject/venv/lib/python3.10/site-packages/django/core/servers/basehttp.py

ERROR 2023-06-06 08:47:58,938 django.request Thread-2 (process_request_thread) 140445250598464 log log.py 241 django.request log_response 40733 Internal Server Error: /person/get-self-person/ 
 path: /home/faridh/Desktop/DeltaProject/venv/lib/python3.10/site-packages/django/utils/log.py

ERROR 2023-06-06 08:47:58,942 django.server Thread-2 (process_request_thread) 140445250598464 basehttp basehttp.py 212 django.server log_message 40733 "POST /person/get-self-person/ HTTP/1.1" 500 677 
 path: /home/faridh/Desktop/DeltaProject/venv/lib/python3.10/site-packages/django/core/servers/basehttp.py

ERROR 2023-06-06 08:50:23,545 django.request Thread-1 (process_request_thread) 140486225425984 log log.py 241 django.request log_response 41556 Internal Server Error: /person/get-self-person/ 
 path: /home/faridh/Desktop/DeltaProject/venv/lib/python3.10/site-packages/django/utils/log.py

ERROR 2023-06-06 08:50:23,547 django.server Thread-1 (process_request_thread) 140486225425984 basehttp basehttp.py 212 django.server log_message 41556 "POST /person/get-self-person/ HTTP/1.1" 500 677 
 path: /home/faridh/Desktop/DeltaProject/venv/lib/python3.10/site-packages/django/core/servers/basehttp.py

ERROR 2023-06-06 08:50:34,797 django.request Thread-2 (process_request_thread) 140486225425984 log log.py 241 django.request log_response 41556 Internal Server Error: /person/get-self-person/ 
 path: /home/faridh/Desktop/DeltaProject/venv/lib/python3.10/site-packages/django/utils/log.py

ERROR 2023-06-06 08:50:34,799 django.server Thread-2 (process_request_thread) 140486225425984 basehttp basehttp.py 212 django.server log_message 41556 "POST /person/get-self-person/ HTTP/1.1" 500 677 
 path: /home/faridh/Desktop/DeltaProject/venv/lib/python3.10/site-packages/django/core/servers/basehttp.py

ERROR 2023-06-06 09:11:51,305 django.request Thread-3 (process_request_thread) 139791293564480 log log.py 241 django.request log_response 42656 Internal Server Error: /person/profil-images/4 
 path: /home/faridh/Desktop/DeltaProject/venv/lib/python3.10/site-packages/django/utils/log.py
Traceback (most recent call last):
  File "/home/faridh/Desktop/DeltaProject/venv/lib/python3.10/site-packages/django/core/handlers/exception.py", line 55, in inner
    response = get_response(request)
  File "/home/faridh/Desktop/DeltaProject/venv/lib/python3.10/site-packages/django/utils/deprecation.py", line 136, in __call__
    response = self.process_response(request, response)
  File "/home/faridh/Desktop/DeltaProject/venv/lib/python3.10/site-packages/django/middleware/common.py", line 108, in process_response
    return self.response_redirect_class(self.get_full_path_with_slash(request))
  File "/home/faridh/Desktop/DeltaProject/venv/lib/python3.10/site-packages/django/middleware/common.py", line 87, in get_full_path_with_slash
    raise RuntimeError(
RuntimeError: You called this URL via POST, but the URL doesn't end in a slash and you have APPEND_SLASH set. Django can't redirect to the slash URL while maintaining POST data. Change your form to point to 127.0.0.1:8000/person/profil-images/4/ (note the trailing slash), or set APPEND_SLASH=False in your Django settings.
ERROR 2023-06-06 09:11:51,335 django.server Thread-3 (process_request_thread) 139791293564480 basehttp basehttp.py 212 django.server log_message 42656 "POST /person/profil-images/4 HTTP/1.1" 500 83541 
 path: /home/faridh/Desktop/DeltaProject/venv/lib/python3.10/site-packages/django/core/servers/basehttp.py

ERROR 2023-06-06 09:12:04,144 django.request Thread-5 (process_request_thread) 139791293564480 log log.py 241 django.request log_response 42656 Not Implemented: /person/profil-images/4/ 
 path: /home/faridh/Desktop/DeltaProject/venv/lib/python3.10/site-packages/django/utils/log.py

ERROR 2023-06-06 09:12:04,146 django.server Thread-5 (process_request_thread) 139791293564480 basehttp basehttp.py 212 django.server log_message 42656 "GET /person/profil-images/4/ HTTP/1.1" 501 39 
 path: /home/faridh/Desktop/DeltaProject/venv/lib/python3.10/site-packages/django/core/servers/basehttp.py

ERROR 2023-06-06 13:36:49,028 django.request Thread-2 (process_request_thread) 140564168177216 log log.py 241 django.request log_response 45375 Internal Server Error: /person/update-person-address/ 
 path: /home/faridh/Desktop/DeltaProject/venv/lib/python3.10/site-packages/django/utils/log.py
Traceback (most recent call last):
  File "/home/faridh/Desktop/DeltaProject/Project/DjAdvanced/DjApp/managements_controller/TokenController.py", line 22, in get_person_from_access_token
    decoded_token = jwt.decode(
  File "/home/faridh/Desktop/DeltaProject/venv/lib/python3.10/site-packages/jwt/api_jwt.py", line 210, in decode
    decoded = self.decode_complete(
  File "/home/faridh/Desktop/DeltaProject/venv/lib/python3.10/site-packages/jwt/api_jwt.py", line 162, in decode_complete
    self._validate_claims(
  File "/home/faridh/Desktop/DeltaProject/venv/lib/python3.10/site-packages/jwt/api_jwt.py", line 248, in _validate_claims
    self._validate_exp(payload, now, leeway)
  File "/home/faridh/Desktop/DeltaProject/venv/lib/python3.10/site-packages/jwt/api_jwt.py", line 304, in _validate_exp
    raise ExpiredSignatureError("Signature has expired")
jwt.exceptions.ExpiredSignatureError: Signature has expired

During handling of the above exception, another exception occurred:

Traceback (most recent call last):
  File "/home/faridh/Desktop/DeltaProject/venv/lib/python3.10/site-packages/sqlalchemy/engine/base.py", line 1968, in _exec_single_context
    self.dialect.do_execute(
  File "/home/faridh/Desktop/DeltaProject/venv/lib/python3.10/site-packages/sqlalchemy/engine/default.py", line 920, in do_execute
    cursor.execute(statement, parameters)
psycopg2.OperationalError: could not receive data from server: Connection timed out
SSL SYSCALL error: Connection timed out


The above exception was the direct cause of the following exception:

Traceback (most recent call last):
  File "/home/faridh/Desktop/DeltaProject/venv/lib/python3.10/site-packages/django/core/handlers/exception.py", line 55, in inner
    response = get_response(request)
  File "/home/faridh/Desktop/DeltaProject/venv/lib/python3.10/site-packages/django/core/handlers/base.py", line 197, in _get_response
    response = wrapped_callback(request, *callback_args, **callback_kwargs)
  File "/home/faridh/Desktop/DeltaProject/venv/lib/python3.10/site-packages/django/views/decorators/csrf.py", line 56, in wrapper_view
    return view_func(*args, **kwargs)
  File "/home/faridh/Desktop/DeltaProject/Project/DjAdvanced/DjApp/decorators.py", line 63, in inner
    response = func(request, *args, **kwargs)
  File "/home/faridh/Desktop/DeltaProject/Project/DjAdvanced/DjApp/decorators.py", line 129, in wrapper
    person_and_tokens = get_person_from_access_token(
  File "/home/faridh/Desktop/DeltaProject/Project/DjAdvanced/DjApp/managements_controller/TokenController.py", line 27, in get_person_from_access_token
    return handle_expired_access_token(request, session)
  File "/home/faridh/Desktop/DeltaProject/Project/DjAdvanced/DjApp/managements_controller/TokenController.py", line 56, in handle_expired_access_token
    person = session.query(Person).get(person_id)
  File "<string>", line 2, in get
  File "/home/faridh/Desktop/DeltaProject/venv/lib/python3.10/site-packages/sqlalchemy/util/deprecations.py", line 389, in warned
    return fn(*args, **kwargs)  # type: ignore[no-any-return]
  File "/home/faridh/Desktop/DeltaProject/venv/lib/python3.10/site-packages/sqlalchemy/orm/query.py", line 1130, in get
    return self._get_impl(ident, loading.load_on_pk_identity)
  File "/home/faridh/Desktop/DeltaProject/venv/lib/python3.10/site-packages/sqlalchemy/orm/query.py", line 1139, in _get_impl
    return self.session._get_impl(
  File "/home/faridh/Desktop/DeltaProject/venv/lib/python3.10/site-packages/sqlalchemy/orm/session.py", line 3675, in _get_impl
    return db_load_fn(
  File "/home/faridh/Desktop/DeltaProject/venv/lib/python3.10/site-packages/sqlalchemy/orm/loading.py", line 668, in load_on_pk_identity
    session.execute(
  File "/home/faridh/Desktop/DeltaProject/venv/lib/python3.10/site-packages/sqlalchemy/orm/session.py", line 2232, in execute
    return self._execute_internal(
  File "/home/faridh/Desktop/DeltaProject/venv/lib/python3.10/site-packages/sqlalchemy/orm/session.py", line 2127, in _execute_internal
    result: Result[Any] = compile_state_cls.orm_execute_statement(
  File "/home/faridh/Desktop/DeltaProject/venv/lib/python3.10/site-packages/sqlalchemy/orm/context.py", line 293, in orm_execute_statement
    result = conn.execute(
  File "/home/faridh/Desktop/DeltaProject/venv/lib/python3.10/site-packages/sqlalchemy/engine/base.py", line 1413, in execute
    return meth(
  File "/home/faridh/Desktop/DeltaProject/venv/lib/python3.10/site-packages/sqlalchemy/sql/elements.py", line 483, in _execute_on_connection
    return connection._execute_clauseelement(
  File "/home/faridh/Desktop/DeltaProject/venv/lib/python3.10/site-packages/sqlalchemy/engine/base.py", line 1637, in _execute_clauseelement
    ret = self._execute_context(
  File "/home/faridh/Desktop/DeltaProject/venv/lib/python3.10/site-packages/sqlalchemy/engine/base.py", line 1846, in _execute_context
    return self._exec_single_context(
  File "/home/faridh/Desktop/DeltaProject/venv/lib/python3.10/site-packages/sqlalchemy/engine/base.py", line 1987, in _exec_single_context
    self._handle_dbapi_exception(
  File "/home/faridh/Desktop/DeltaProject/venv/lib/python3.10/site-packages/sqlalchemy/engine/base.py", line 2344, in _handle_dbapi_exception
    raise sqlalchemy_exception.with_traceback(exc_info[2]) from e
  File "/home/faridh/Desktop/DeltaProject/venv/lib/python3.10/site-packages/sqlalchemy/engine/base.py", line 1968, in _exec_single_context
    self.dialect.do_execute(
  File "/home/faridh/Desktop/DeltaProject/venv/lib/python3.10/site-packages/sqlalchemy/engine/default.py", line 920, in do_execute
    cursor.execute(statement, parameters)
sqlalchemy.exc.OperationalError: (psycopg2.OperationalError) could not receive data from server: Connection timed out
SSL SYSCALL error: Connection timed out

[SQL: SELECT persons.id AS persons_id, persons.username AS persons_username, persons.first_name AS persons_first_name, persons.last_name AS persons_last_name, persons.gender AS persons_gender, persons.email AS persons_email, persons._password AS persons__password, persons.location_id AS persons_location_id, persons.phone_number_id AS persons_phone_number_id, persons.person_type AS persons_person_type, persons.phone_verify AS persons_phone_verify, persons.active AS persons_active, persons.refresh_token_id AS persons_refresh_token_id, persons.created_at AS persons_created_at, persons.updated_at AS persons_updated_at, persons.deleted_at AS persons_deleted_at 
FROM persons 
WHERE persons.id = %(pk_1)s]
[parameters: {'pk_1': 15}]
(Background on this error at: https://sqlalche.me/e/20/e3q8)
WARNING 2023-06-06 13:56:39,030 django.request Thread-5 (process_request_thread) 140564168177216 log log.py 241 django.request log_response 45375 Not Found: /person/change_password/ 
 path: /home/faridh/Desktop/DeltaProject/venv/lib/python3.10/site-packages/django/utils/log.py

WARNING 2023-06-06 13:56:39,033 django.server Thread-5 (process_request_thread) 140564168177216 basehttp basehttp.py 212 django.server log_message 45375 "POST /person/change_password/ HTTP/1.1" 404 7885 
 path: /home/faridh/Desktop/DeltaProject/venv/lib/python3.10/site-packages/django/core/servers/basehttp.py

WARNING 2023-06-06 13:57:05,886 django.request Thread-7 (process_request_thread) 140564168177216 log log.py 241 django.request log_response 45375 Unauthorized: /person/change-password/ 
 path: /home/faridh/Desktop/DeltaProject/venv/lib/python3.10/site-packages/django/utils/log.py

WARNING 2023-06-06 13:57:05,888 django.server Thread-7 (process_request_thread) 140564168177216 basehttp basehttp.py 212 django.server log_message 45375 "POST /person/change-password/ HTTP/1.1" 401 48 
 path: /home/faridh/Desktop/DeltaProject/venv/lib/python3.10/site-packages/django/core/servers/basehttp.py

WARNING 2023-06-06 13:57:31,158 django.request Thread-9 (process_request_thread) 140564168177216 log log.py 241 django.request log_response 45375 Unauthorized: /person/change-password/ 
 path: /home/faridh/Desktop/DeltaProject/venv/lib/python3.10/site-packages/django/utils/log.py

WARNING 2023-06-06 13:57:31,159 django.server Thread-9 (process_request_thread) 140564168177216 basehttp basehttp.py 212 django.server log_message 45375 "POST /person/change-password/ HTTP/1.1" 401 48 
 path: /home/faridh/Desktop/DeltaProject/venv/lib/python3.10/site-packages/django/core/servers/basehttp.py

WARNING 2023-06-06 13:57:40,977 django.request Thread-10 (process_request_thread) 140564168177216 log log.py 241 django.request log_response 45375 Unauthorized: /person/change-password/ 
 path: /home/faridh/Desktop/DeltaProject/venv/lib/python3.10/site-packages/django/utils/log.py

WARNING 2023-06-06 13:57:40,979 django.server Thread-10 (process_request_thread) 140564168177216 basehttp basehttp.py 212 django.server log_message 45375 "POST /person/change-password/ HTTP/1.1" 401 48 
 path: /home/faridh/Desktop/DeltaProject/venv/lib/python3.10/site-packages/django/core/servers/basehttp.py

WARNING 2023-06-06 13:58:11,992 django.request Thread-11 (process_request_thread) 140564168177216 log log.py 241 django.request log_response 45375 Unauthorized: /person/change-password/ 
 path: /home/faridh/Desktop/DeltaProject/venv/lib/python3.10/site-packages/django/utils/log.py

WARNING 2023-06-06 13:58:11,993 django.server Thread-11 (process_request_thread) 140564168177216 basehttp basehttp.py 212 django.server log_message 45375 "POST /person/change-password/ HTTP/1.1" 401 48 
 path: /home/faridh/Desktop/DeltaProject/venv/lib/python3.10/site-packages/django/core/servers/basehttp.py

WARNING 2023-06-06 14:00:40,371 django.request Thread-14 (process_request_thread) 140564168177216 log log.py 241 django.request log_response 45375 Unauthorized: /person/change-password/ 
 path: /home/faridh/Desktop/DeltaProject/venv/lib/python3.10/site-packages/django/utils/log.py

WARNING 2023-06-06 14:00:40,372 django.server Thread-14 (process_request_thread) 140564168177216 basehttp basehttp.py 212 django.server log_message 45375 "POST /person/change-password/ HTTP/1.1" 401 48 
 path: /home/faridh/Desktop/DeltaProject/venv/lib/python3.10/site-packages/django/core/servers/basehttp.py

WARNING 2023-06-06 14:01:01,914 django.request Thread-16 (process_request_thread) 140564168177216 log log.py 241 django.request log_response 45375 Unauthorized: /person/change-password/ 
 path: /home/faridh/Desktop/DeltaProject/venv/lib/python3.10/site-packages/django/utils/log.py

WARNING 2023-06-06 14:01:01,916 django.server Thread-16 (process_request_thread) 140564168177216 basehttp basehttp.py 212 django.server log_message 45375 "POST /person/change-password/ HTTP/1.1" 401 48 
 path: /home/faridh/Desktop/DeltaProject/venv/lib/python3.10/site-packages/django/core/servers/basehttp.py

WARNING 2023-06-06 14:01:12,382 django.request Thread-17 (process_request_thread) 140564168177216 log log.py 241 django.request log_response 45375 Unauthorized: /person/change-password/ 
 path: /home/faridh/Desktop/DeltaProject/venv/lib/python3.10/site-packages/django/utils/log.py

WARNING 2023-06-06 14:01:12,383 django.server Thread-17 (process_request_thread) 140564168177216 basehttp basehttp.py 212 django.server log_message 45375 "POST /person/change-password/ HTTP/1.1" 401 48 
 path: /home/faridh/Desktop/DeltaProject/venv/lib/python3.10/site-packages/django/core/servers/basehttp.py

WARNING 2023-06-06 14:01:25,485 django.request Thread-18 (process_request_thread) 140564168177216 log log.py 241 django.request log_response 45375 Unauthorized: /person/change-password/ 
 path: /home/faridh/Desktop/DeltaProject/venv/lib/python3.10/site-packages/django/utils/log.py

WARNING 2023-06-06 14:01:25,491 django.server Thread-18 (process_request_thread) 140564168177216 basehttp basehttp.py 212 django.server log_message 45375 "POST /person/change-password/ HTTP/1.1" 401 48 
 path: /home/faridh/Desktop/DeltaProject/venv/lib/python3.10/site-packages/django/core/servers/basehttp.py

WARNING 2023-06-06 14:01:30,144 django.request Thread-19 (process_request_thread) 140564168177216 log log.py 241 django.request log_response 45375 Unauthorized: /person/change-password/ 
 path: /home/faridh/Desktop/DeltaProject/venv/lib/python3.10/site-packages/django/utils/log.py

WARNING 2023-06-06 14:01:30,145 django.server Thread-19 (process_request_thread) 140564168177216 basehttp basehttp.py 212 django.server log_message 45375 "POST /person/change-password/ HTTP/1.1" 401 48 
 path: /home/faridh/Desktop/DeltaProject/venv/lib/python3.10/site-packages/django/core/servers/basehttp.py

ERROR 2023-06-06 14:33:49,151 django.request Thread-1 (process_request_thread) 140533669295680 log log.py 241 django.request log_response 54683 Internal Server Error: /person/update/ 
 path: /home/faridh/Desktop/DeltaProject/venv/lib/python3.10/site-packages/django/utils/log.py
Traceback (most recent call last):
  File "/home/faridh/Desktop/DeltaProject/venv/lib/python3.10/site-packages/sqlalchemy/engine/base.py", line 1968, in _exec_single_context
    self.dialect.do_execute(
  File "/home/faridh/Desktop/DeltaProject/venv/lib/python3.10/site-packages/sqlalchemy/engine/default.py", line 920, in do_execute
    cursor.execute(statement, parameters)
psycopg2.errors.UniqueViolation: duplicate key value violates unique constraint "persons_email_key"
DETAIL:  Key (email)=(\x3078316a4661754c2f774b75564377364e536c797376474e446f78354d66323856646d7649724c43506a673d) already exists.


The above exception was the direct cause of the following exception:

Traceback (most recent call last):
  File "/home/faridh/Desktop/DeltaProject/venv/lib/python3.10/site-packages/django/core/handlers/exception.py", line 55, in inner
    response = get_response(request)
  File "/home/faridh/Desktop/DeltaProject/venv/lib/python3.10/site-packages/django/core/handlers/base.py", line 197, in _get_response
    response = wrapped_callback(request, *callback_args, **callback_kwargs)
  File "/home/faridh/Desktop/DeltaProject/venv/lib/python3.10/site-packages/django/views/decorators/csrf.py", line 56, in wrapper_view
    return view_func(*args, **kwargs)
  File "/home/faridh/Desktop/DeltaProject/Project/DjAdvanced/DjApp/decorators.py", line 60, in inner
    with session_scope() as session:
  File "/usr/lib/python3.10/contextlib.py", line 142, in __exit__
    next(self.gen)
  File "/home/faridh/Desktop/DeltaProject/Project/DjAdvanced/DjApp/helpers.py", line 145, in session_scope
    session.commit()
  File "/home/faridh/Desktop/DeltaProject/venv/lib/python3.10/site-packages/sqlalchemy/orm/session.py", line 1906, in commit
    trans.commit(_to_root=True)
  File "<string>", line 2, in commit
  File "/home/faridh/Desktop/DeltaProject/venv/lib/python3.10/site-packages/sqlalchemy/orm/state_changes.py", line 137, in _go
    ret_value = fn(self, *arg, **kw)
  File "/home/faridh/Desktop/DeltaProject/venv/lib/python3.10/site-packages/sqlalchemy/orm/session.py", line 1221, in commit
    self._prepare_impl()
  File "<string>", line 2, in _prepare_impl
  File "/home/faridh/Desktop/DeltaProject/venv/lib/python3.10/site-packages/sqlalchemy/orm/state_changes.py", line 137, in _go
    ret_value = fn(self, *arg, **kw)
  File "/home/faridh/Desktop/DeltaProject/venv/lib/python3.10/site-packages/sqlalchemy/orm/session.py", line 1196, in _prepare_impl
    self.session.flush()
  File "/home/faridh/Desktop/DeltaProject/venv/lib/python3.10/site-packages/sqlalchemy/orm/session.py", line 4154, in flush
    self._flush(objects)
  File "/home/faridh/Desktop/DeltaProject/venv/lib/python3.10/site-packages/sqlalchemy/orm/session.py", line 4290, in _flush
    with util.safe_reraise():
  File "/home/faridh/Desktop/DeltaProject/venv/lib/python3.10/site-packages/sqlalchemy/util/langhelpers.py", line 147, in __exit__
    raise exc_value.with_traceback(exc_tb)
  File "/home/faridh/Desktop/DeltaProject/venv/lib/python3.10/site-packages/sqlalchemy/orm/session.py", line 4251, in _flush
    flush_context.execute()
  File "/home/faridh/Desktop/DeltaProject/venv/lib/python3.10/site-packages/sqlalchemy/orm/unitofwork.py", line 467, in execute
    rec.execute(self)
  File "/home/faridh/Desktop/DeltaProject/venv/lib/python3.10/site-packages/sqlalchemy/orm/unitofwork.py", line 644, in execute
    util.preloaded.orm_persistence.save_obj(
  File "/home/faridh/Desktop/DeltaProject/venv/lib/python3.10/site-packages/sqlalchemy/orm/persistence.py", line 85, in save_obj
    _emit_update_statements(
  File "/home/faridh/Desktop/DeltaProject/venv/lib/python3.10/site-packages/sqlalchemy/orm/persistence.py", line 904, in _emit_update_statements
    c = connection.execute(
  File "/home/faridh/Desktop/DeltaProject/venv/lib/python3.10/site-packages/sqlalchemy/engine/base.py", line 1413, in execute
    return meth(
  File "/home/faridh/Desktop/DeltaProject/venv/lib/python3.10/site-packages/sqlalchemy/sql/elements.py", line 483, in _execute_on_connection
    return connection._execute_clauseelement(
  File "/home/faridh/Desktop/DeltaProject/venv/lib/python3.10/site-packages/sqlalchemy/engine/base.py", line 1637, in _execute_clauseelement
    ret = self._execute_context(
  File "/home/faridh/Desktop/DeltaProject/venv/lib/python3.10/site-packages/sqlalchemy/engine/base.py", line 1846, in _execute_context
    return self._exec_single_context(
  File "/home/faridh/Desktop/DeltaProject/venv/lib/python3.10/site-packages/sqlalchemy/engine/base.py", line 1987, in _exec_single_context
    self._handle_dbapi_exception(
  File "/home/faridh/Desktop/DeltaProject/venv/lib/python3.10/site-packages/sqlalchemy/engine/base.py", line 2344, in _handle_dbapi_exception
    raise sqlalchemy_exception.with_traceback(exc_info[2]) from e
  File "/home/faridh/Desktop/DeltaProject/venv/lib/python3.10/site-packages/sqlalchemy/engine/base.py", line 1968, in _exec_single_context
    self.dialect.do_execute(
  File "/home/faridh/Desktop/DeltaProject/venv/lib/python3.10/site-packages/sqlalchemy/engine/default.py", line 920, in do_execute
    cursor.execute(statement, parameters)
sqlalchemy.exc.IntegrityError: (psycopg2.errors.UniqueViolation) duplicate key value violates unique constraint "persons_email_key"
DETAIL:  Key (email)=(\x3078316a4661754c2f774b75564377364e536c797376474e446f78354d66323856646d7649724c43506a673d) already exists.

[SQL: UPDATE persons SET first_name=%(first_name)s, last_name=%(last_name)s, email=%(email)s, active=%(active)s, updated_at=%(updated_at)s WHERE persons.id = %(persons_id)s]
[parameters: {'first_name': 'Hebiblii', 'last_name': 'Elcann', 'email': <psycopg2.extensions.Binary object at 0x7fd08ace3c90>, 'active': False, 'updated_at': 'now()', 'persons_id': 15}]
(Background on this error at: https://sqlalche.me/e/20/gkpj)
ERROR 2023-06-06 14:33:49,162 django.server Thread-1 (process_request_thread) 140533669295680 basehttp basehttp.py 212 django.server log_message 54683 "POST /person/update/ HTTP/1.1" 500 229753 
 path: /home/faridh/Desktop/DeltaProject/venv/lib/python3.10/site-packages/django/core/servers/basehttp.py

WARNING 2023-06-06 18:41:28,969 django.request Thread-1 (process_request_thread) 139802125006400 log log.py 241 django.request log_response 12567 Not Found: /password/send-password-reset-link/ 
 path: /home/faridh/Desktop/DeltaProject/venv/lib/python3.10/site-packages/django/utils/log.py

WARNING 2023-06-06 18:41:28,983 django.server Thread-1 (process_request_thread) 139802125006400 basehttp basehttp.py 212 django.server log_message 12567 "POST /password/send-password-reset-link/ HTTP/1.1" 404 4371 
 path: /home/faridh/Desktop/DeltaProject/venv/lib/python3.10/site-packages/django/core/servers/basehttp.py

WARNING 2023-06-06 18:47:04,392 django.request Thread-1 (process_request_thread) 140143861167680 log log.py 241 django.request log_response 13776 Not Found: /give-reset-password-permission/ 
 path: /home/faridh/Desktop/DeltaProject/venv/lib/python3.10/site-packages/django/utils/log.py

WARNING 2023-06-06 18:47:04,400 django.server Thread-1 (process_request_thread) 140143861167680 basehttp basehttp.py 212 django.server log_message 13776 "GET /give-reset-password-permission/?reset_token=eyJhbGciOiJIUzI1NiIsInR5cCI6IkpXVCJ9.eyJwZXJzb25faWQiOjUsImV4cCI6MTY4NjE2MzMwNH0.wUD64qAqBjW0pwjtAiHo7zPuBCmy1YNHF1s9p1FnQWI HTTP/1.1" 404 4498 
 path: /home/faridh/Desktop/DeltaProject/venv/lib/python3.10/site-packages/django/core/servers/basehttp.py

WARNING 2023-06-06 18:47:05,478 django.request Thread-1 (process_request_thread) 140143861167680 log log.py 241 django.request log_response 13776 Not Found: /favicon.ico 
 path: /home/faridh/Desktop/DeltaProject/venv/lib/python3.10/site-packages/django/utils/log.py

WARNING 2023-06-06 18:47:05,480 django.server Thread-1 (process_request_thread) 140143861167680 basehttp basehttp.py 212 django.server log_message 13776 "GET /favicon.ico HTTP/1.1" 404 4301 
 path: /home/faridh/Desktop/DeltaProject/venv/lib/python3.10/site-packages/django/core/servers/basehttp.py

WARNING 2023-06-06 18:58:44,959 django.request Thread-2 (process_request_thread) 140383130830400 log log.py 241 django.request log_response 15288 Not Found: /reset-password/ 
 path: /home/faridh/Desktop/DeltaProject/venv/lib/python3.10/site-packages/django/utils/log.py

WARNING 2023-06-06 18:58:44,979 django.server Thread-2 (process_request_thread) 140383130830400 basehttp basehttp.py 212 django.server log_message 15288 "POST /reset-password/ HTTP/1.1" 404 4314 
 path: /home/faridh/Desktop/DeltaProject/venv/lib/python3.10/site-packages/django/core/servers/basehttp.py

